<?xml version="1.0"?>
<robot name="my_robot">

    <material name="green">
        <color rgba="0 0.5 0 1" />
    </material>

    <material name="blue">
        <color rgba="0 0 0.5 1" />
    </material>

    <material name="grey">
        <color rgba="0.5 0.5 0.5 1" />
    </material>

    <link name="base_link">
        <visual>
            <geometry>
                <box size="0.6 0.4 0.2" />
            </geometry>
            <origin xyz="0 0 0.1" rpy="0 0 0" />
            <material name="green" />
        </visual>
    </link>


    <link name="second_link">
        <visual>
            <geometry>
                <cylinder radius="0.1" length="0.2" />
            </geometry>
            <origin xyz="0 0 0.1" rpy="0 0 0" />
            <material name="grey" />
        </visual>
    </link>

    <link name="third_link">
        <visual>
            <geometry>
                <box size="0.1 0.1 0.1" />
            </geometry>
            <origin xyz="0 0 0.05" rpy="0 0 0" />
            <material name="grey" />
        </visual>
    </link>

    <link name="fourth_link">
        <visual>
            <geometry>
                <box size="0.1 0.1 0.1" />
            </geometry>
            <origin xyz="0 0 0.05" rpy="0 0 0" />
            <material name="grey" />
        </visual>
    </link>

    <joint name="base_second_jonit" type="revolute">
        <parent link="base_link" />
        <child link="second_link" />
        <origin xyz="0 0 0.2" rpy="0 0 0" />
        <axis xyz="0 0 1" />
        <limit lower="-1.57" upper="1.57" velocity="100" effort="100" />
    </joint>

    <joint name="secon_third_joint" type="fixed">
        <parent link="second_link" />
        <child link="third_link" />
        <origin xyz="0 0 0.2" rpy="0 0 0" />
    </joint>

    <joint name="third_fourth_joint" type="prismatic">
        <parent link="third_link" />
        <child link="fourth_link" />
        <origin xyz="0 0 0.1" rpy="0 0 0" />
        <axis xyz="0 1 0" />
        <limit lower="0.0" upper="0.2" velocity="100" effort="100" />
    </joint>
</robot>    